2016-11-15 11:00:22,823 - teradata.udaexec - INFO - Initializing UdaExec...
2016-11-15 11:00:22,823 - teradata.udaexec - INFO - Reading config files: ['/etc/udaexec.ini: Not Found', '/Users/vro173/udaexec.ini: Not Found', '/Users/vro173/Documents/Python_programs/udaexec.ini: Not Found']
2016-11-15 11:00:22,823 - teradata.udaexec - INFO - Found run number file: "/Users/vro173/Documents/Python_programs/.runNumber"
2016-11-15 11:00:22,823 - teradata.udaexec - INFO - Cleaning up log files older than 90 days.
2016-11-15 11:00:22,823 - teradata.udaexec - INFO - Removed 0 log files.
2016-11-15 11:00:22,862 - teradata.udaexec - INFO - Checkpoint file not found: /Users/vro173/Documents/Python_programs/HelloWorld.checkpoint
2016-11-15 11:00:22,863 - teradata.udaexec - INFO - No previous checkpoint found, executing from beginning...
2016-11-15 11:00:22,863 - teradata.udaexec - INFO - Execution Details:
/********************************************************************************
 * Application Name: HelloWorld
 *          Version: 1.0
 *       Run Number: 20161115110022-42
 *             Host: acbc32a00557
 *         Platform: Darwin-15.6.0-x86_64-i386-64bit
 *          OS User: vro173
 *   Python Version: 3.5.2
 *  Python Compiler: GCC 4.2.1 Compatible Apple LLVM 4.2 (clang-425.0.28)
 *     Python Build: ('default', 'Jul  2 2016 17:52:12')
 *  UdaExec Version: 15.10.0.20
 *     Program Name: classify_tables.py
 *      Working Dir: /Users/vro173/Documents/Python_programs
 *          Log Dir: /Users/vro173/Documents/Python_programs/logs
 *         Log File: /Users/vro173/Documents/Python_programs/logs/HelloWorld.20161115110022-42.log
 *     Config Files: ['/etc/udaexec.ini: Not Found', '/Users/vro173/udaexec.ini: Not Found', '/Users/vro173/Documents/Python_programs/udaexec.ini: Not Found']
 *      Query Bands: ApplicationName=HelloWorld;Version=1.0;JobID=20161115110022-42;ClientUser=vro173;Production=False;udaAppLogFile=/Users/vro173/Documents/Python_programs/logs/HelloWorld.20161115110022-42.log;UtilityName=PyTd;UtilityVersion=15.10.0.20
********************************************************************************/
2016-11-15 11:00:22,869 - teradata.udaexec - INFO - Creating connection: {'system': 'oneview', 'password': 'XXXXXX', 'username': 'vro173', 'method': 'odbc'}
2016-11-15 11:00:22,869 - teradata.tdodbc - INFO - Loading ODBC Library: libiodbc.dylib
2016-11-15 11:00:22,875 - teradata.tdodbc - INFO - Available drivers: Amazon Redshift, MapR Drill ODBC Driver, MySQL ODBC 5.3 ANSI Driver, MySQL ODBC 5.3 Unicode Driver, PostgreSQL Unicode, Simba SQL Server ODBC Driver, Teradata
2016-11-15 11:00:31,815 - teradata.udaexec - INFO - Connection successful. Duration: 8.946 seconds. Details: {'system': 'oneview', 'password': 'XXXXXX', 'username': 'vro173', 'method': 'odbc'}
2016-11-15 11:00:45,830 - teradata.udaexec - INFO - Query Successful. Duration: 13.045 seconds, Rows: 21, Query: SELECT DATABASENAME, TABLENAME, COLUMNNAME FROM DBC.COLUMNS where DATABASENAME='PMASTRAT_TB' AND TABLENAME = 'AND_CAT1_AFFILIATE_122006';
2016-11-15 11:00:45,838 - teradata.udaexec - ERROR - Uncaught exception
Traceback (most recent call last):
  File "classify_tables.py", line 55, in <module>
    my_data = {"DATABASENAME":databasename , "TABLENAME":tablename, "COLUMNNAME":columnname, "NPI_FLAG":npi_flag, "JOB_FLAG":job_flag, "role":role}
NameError: name 'role' is not defined
2016-11-15 11:00:45,839 - teradata.tdodbc - WARNING - 1 open connections found on exit, attempting to close...
2016-11-15 11:00:45,919 - teradata.udaexec - INFO - UdaExec exiting.
