2016-10-25 14:26:59,636 - teradata.udaexec - INFO - Initializing UdaExec...
2016-10-25 14:26:59,636 - teradata.udaexec - INFO - Reading config files: ['/etc/udaexec.ini: Not Found', '/Users/vro173/udaexec.ini: Not Found', '/Users/vro173/Documents/Python_programs/udaexec.ini: Not Found']
2016-10-25 14:26:59,636 - teradata.udaexec - INFO - No previous run number found as /Users/vro173/Documents/Python_programs/.runNumber does not exist. Initializing run number to 1
2016-10-25 14:26:59,636 - teradata.udaexec - INFO - Cleaning up log files older than 90 days.
2016-10-25 14:26:59,636 - teradata.udaexec - INFO - Removed 0 log files.
2016-10-25 14:27:00,313 - teradata.udaexec - INFO - Checkpoint file not found: /Users/vro173/Documents/Python_programs/HelloWorld.checkpoint
2016-10-25 14:27:00,313 - teradata.udaexec - INFO - No previous checkpoint found, executing from beginning...
2016-10-25 14:27:00,313 - teradata.udaexec - INFO - Execution Details:
/********************************************************************************
 * Application Name: HelloWorld
 *          Version: 1.0
 *       Run Number: 20161025142659-1
 *             Host: acbc32a00557
 *         Platform: Darwin-15.6.0-x86_64-i386-64bit
 *          OS User: vro173
 *   Python Version: 3.5.2
 *  Python Compiler: GCC 4.2.1 Compatible Apple LLVM 4.2 (clang-425.0.28)
 *     Python Build: ('default', 'Jul  2 2016 17:52:12')
 *  UdaExec Version: 15.10.0.20
 *     Program Name: classify_tables.py
 *      Working Dir: /Users/vro173/Documents/Python_programs
 *          Log Dir: /Users/vro173/Documents/Python_programs/logs
 *         Log File: /Users/vro173/Documents/Python_programs/logs/HelloWorld.20161025142659-1.log
 *     Config Files: ['/etc/udaexec.ini: Not Found', '/Users/vro173/udaexec.ini: Not Found', '/Users/vro173/Documents/Python_programs/udaexec.ini: Not Found']
 *      Query Bands: ApplicationName=HelloWorld;Version=1.0;JobID=20161025142659-1;ClientUser=vro173;Production=False;udaAppLogFile=/Users/vro173/Documents/Python_programs/logs/HelloWorld.20161025142659-1.log;UtilityName=PyTd;UtilityVersion=15.10.0.20
********************************************************************************/
2016-10-25 14:27:00,332 - teradata.udaexec - INFO - Creating connection: {'method': 'odbc', 'system': 'oneview', 'password': 'XXXXXX', 'username': 'vro173'}
2016-10-25 14:27:00,333 - teradata.tdodbc - INFO - Loading ODBC Library: libiodbc.dylib
2016-10-25 14:27:00,340 - teradata.tdodbc - INFO - Available drivers: Amazon Redshift, MapR Drill ODBC Driver, MySQL ODBC 5.3 ANSI Driver, MySQL ODBC 5.3 Unicode Driver, PostgreSQL Unicode, Simba SQL Server ODBC Driver, Teradata
2016-10-25 14:27:00,661 - teradata.udaexec - ERROR - Unable to create connection: {'method': 'odbc', 'system': 'oneview', 'password': 'XXXXXX', 'username': 'vro173'}
Traceback (most recent call last):
  File "/Users/vro173/anaconda/lib/python3.5/site-packages/teradata/udaexec.py", line 183, in connect
    **args))
  File "/Users/vro173/anaconda/lib/python3.5/site-packages/teradata/tdodbc.py", line 432, in __init__
    checkStatus(rc, hDbc=self.hDbc, method="SQLDriverConnectW")
  File "/Users/vro173/anaconda/lib/python3.5/site-packages/teradata/tdodbc.py", line 209, in checkStatus
    raise DatabaseError(i[2], u"[{}] {}".format(i[0], msg), i[0])
teradata.api.DatabaseError: (65, "[08001] [Teradata][Unix system error]  65 Socket error - The Teradata server can't currently be reached over this network")
2016-10-25 14:27:00,664 - teradata.udaexec - ERROR - Uncaught exception
Traceback (most recent call last):
  File "classify_tables.py", line 7, in <module>
    username="vro173", password="Geethu30");
  File "/Users/vro173/anaconda/lib/python3.5/site-packages/teradata/udaexec.py", line 183, in connect
    **args))
  File "/Users/vro173/anaconda/lib/python3.5/site-packages/teradata/tdodbc.py", line 432, in __init__
    checkStatus(rc, hDbc=self.hDbc, method="SQLDriverConnectW")
  File "/Users/vro173/anaconda/lib/python3.5/site-packages/teradata/tdodbc.py", line 209, in checkStatus
    raise DatabaseError(i[2], u"[{}] {}".format(i[0], msg), i[0])
teradata.api.DatabaseError: (65, "[08001] [Teradata][Unix system error]  65 Socket error - The Teradata server can't currently be reached over this network")
2016-10-25 14:27:00,666 - teradata.udaexec - INFO - UdaExec exiting.
