2016-10-25 14:38:28,171 - teradata.udaexec - INFO - Initializing UdaExec...
2016-10-25 14:38:28,171 - teradata.udaexec - INFO - Reading config files: ['/etc/udaexec.ini: Not Found', '/Users/vro173/udaexec.ini: Not Found', '/Users/vro173/Documents/Python_programs/udaexec.ini: Not Found']
2016-10-25 14:38:28,171 - teradata.udaexec - INFO - Found run number file: "/Users/vro173/Documents/Python_programs/.runNumber"
2016-10-25 14:38:28,171 - teradata.udaexec - INFO - Cleaning up log files older than 90 days.
2016-10-25 14:38:28,171 - teradata.udaexec - INFO - Removed 0 log files.
2016-10-25 14:38:28,253 - teradata.udaexec - INFO - Checkpoint file not found: /Users/vro173/Documents/Python_programs/HelloWorld.checkpoint
2016-10-25 14:38:28,253 - teradata.udaexec - INFO - No previous checkpoint found, executing from beginning...
2016-10-25 14:38:28,253 - teradata.udaexec - INFO - Execution Details:
/********************************************************************************
 * Application Name: HelloWorld
 *          Version: 1.0
 *       Run Number: 20161025143828-4
 *             Host: acbc32a00557
 *         Platform: Darwin-15.6.0-x86_64-i386-64bit
 *          OS User: vro173
 *   Python Version: 3.5.2
 *  Python Compiler: GCC 4.2.1 Compatible Apple LLVM 4.2 (clang-425.0.28)
 *     Python Build: ('default', 'Jul  2 2016 17:52:12')
 *  UdaExec Version: 15.10.0.20
 *     Program Name: classify_tables.py
 *      Working Dir: /Users/vro173/Documents/Python_programs
 *          Log Dir: /Users/vro173/Documents/Python_programs/logs
 *         Log File: /Users/vro173/Documents/Python_programs/logs/HelloWorld.20161025143828-4.log
 *     Config Files: ['/etc/udaexec.ini: Not Found', '/Users/vro173/udaexec.ini: Not Found', '/Users/vro173/Documents/Python_programs/udaexec.ini: Not Found']
 *      Query Bands: ApplicationName=HelloWorld;Version=1.0;JobID=20161025143828-4;ClientUser=vro173;Production=False;udaAppLogFile=/Users/vro173/Documents/Python_programs/logs/HelloWorld.20161025143828-4.log;UtilityName=PyTd;UtilityVersion=15.10.0.20
********************************************************************************/
2016-10-25 14:38:28,268 - teradata.udaexec - INFO - Creating connection: {'username': 'vro173', 'password': 'XXXXXX', 'method': 'odbc', 'system': 'oneview'}
2016-10-25 14:38:28,269 - teradata.tdodbc - INFO - Loading ODBC Library: libiodbc.dylib
2016-10-25 14:38:28,277 - teradata.tdodbc - INFO - Available drivers: Amazon Redshift, MapR Drill ODBC Driver, MySQL ODBC 5.3 ANSI Driver, MySQL ODBC 5.3 Unicode Driver, PostgreSQL Unicode, Simba SQL Server ODBC Driver, Teradata
2016-10-25 14:38:36,595 - teradata.udaexec - INFO - Connection successful. Duration: 8.326 seconds. Details: {'username': 'vro173', 'password': 'XXXXXX', 'method': 'odbc', 'system': 'oneview'}
2016-10-25 14:39:12,458 - teradata.udaexec - ERROR - Uncaught exception
Traceback (most recent call last):
  File "classify_tables.py", line 9, in <module>
    for row in session.execute("SELECT * from PSDP.AND_41789_042009"):
  File "/Users/vro173/anaconda/lib/python3.5/site-packages/teradata/udaexec.py", line 675, in execute
    self.internalCursor.execute(query, params, **kwargs)
  File "/Users/vro173/anaconda/lib/python3.5/site-packages/teradata/udaexec.py", line 745, in execute
    self._execute(self.cursor.execute, query, params, **kwargs)
  File "/Users/vro173/anaconda/lib/python3.5/site-packages/teradata/udaexec.py", line 790, in _execute
    func(query, params, **kwargs)
  File "/Users/vro173/anaconda/lib/python3.5/site-packages/teradata/tdodbc.py", line 591, in execute
    self.hStmt, _inputStr(_convertLineFeeds(query)), SQL_NTS)
KeyboardInterrupt
2016-10-25 14:39:12,465 - teradata.tdodbc - WARNING - 1 open connections found on exit, attempting to close...
2016-10-25 14:39:12,581 - teradata.udaexec - INFO - UdaExec exiting.
